Workbook
Name teste: #REF!

Sheet Corpo
A1: <html> <body style='font-family:Calibri;'> <h2><strong>Faturamento de Pe&ccedil;as Vans @data</strong></h2> <br> <p> <table align=""""center"""" border=""""1"""" cellpadding=""""1"""" cellspacing=""""1"""" style="width:100%" style="text-align:center"> <colgroup> <col span="4" style="background-color: #A9A9A9"> <col span="1"> <col span="1" style="background-color: #F0E68C"> <col span="2" style="background-color: #ADD8E6"> <col span="2" style="background-color: #87CEFA"> <col span="1" style="background-color: #FFA07A"> </colgroup> <thead> <tr> <th scope=""""col"""" style="width:6%" border-left: 1px solid #DCDCDC><strong>Conta</strong></th> <th scope=""""col"""" style="width:34%"><strong>Razão Social</strong></th> <th scope=""""col"""" style="width:10%"><strong>Cidade / UF </strong></th> <th scope=""""col"""" style="width:2%" border-right: 1px solid #DCDCDC;><strong>Objetivo</strong></th> <th scope=""""col"""">&nbsp;</th> <th scope=""""col"""" style="width:9%" border-right: 1px solid #DCDCDC><strong>Bruto </strong></th> <th scope=""""col"""" style="width:9%"><strong>à processar </strong></th> <th scope=""""col"""" style="width:8%"><strong>Garantia</strong></th> <th scope=""""col"""" style="width:9%" border-right: 1px solid #DCDCDC><strong>Realizado</strong></th> <th scope=""""col"""" style="width:6%"><strong>Performance</strong></th> <th scope=""""col"""" style="width:7%" border-right: 1px solid #DCDCDC><strong>Falta 100%</strong></th> </tr> <tr> <td>@conta</th> <td>@razao</th> <td>@cidade</th> <td>@uf</th> <td>&nbsp;</th> <td>@objetivo</th> <td>@realfat</th> <td>@realgar</th> <td>@realobj</th> <td>@perf</th> <td>@falta</th> </tr> </thead> <tbody> </tbody> </table> <br> <br> <p>Os valores para o fechamento foram atualizados desprezando as Notas Fiscais canceladas/devolvidas.<br> <p>Os valores à processar não estão incluso no realizado.<br> <br> <br> <p>Atenciosamente,<br> Mercedes Benz Cars & Vans do Brasil Ltda.</p> </body> </html>

Sheet Composicao
A1: Conta | B1: Título | C1: Corpo | D1: Destinatário | E1: Cópia | F1: Envia?
A2: 40532251 | B2: =CONCATENATE("Faturamento de Peças Vans Agosto 2024 - ",A2," - ",TEXT('Envio diario'!$D$1,"dd/mmm/aaaa")) -> Faturamento de Peças Vans Agosto 2024 - 40532251 - 09/mar/2026 | C2: =SUBSTITUTE(SUBSTITUTE(SUBSTITUTE(SUBSTITUTE(SUBSTITUTE(SUBSTITUTE(SUBSTITUTE(SUBSTITUTE(SUBSTITUTE(SUBSTITUTE(SUBSTITUTE( Corpo!$A$1, "@data", TEXT('Envio diario'!$D$1,"dd/mmm/aaaa") ), "@conta", $A2 ), "@razao", VLOOKUP($A2,'Envio diario'!$B:$J,2,0) ), "@cidade", VLOOKUP($A2,'Envio diario'!$B:$J,3,0) ), "@uf", IF(VLOOKUP($A2,'Envio diario'!$B:$J,4,0)>100,TEXT(VLOOKUP($A2,'Envio diario'!$B:$J,4,0),"0.000,00"),TEXT(VLOOKUP($A2,'Envio diario'!$B:$J,4,0),"0,00"))), "@objetivo", IF(VLOOKUP($A2,'Envio diario'!$B:$J,7,0)>100,TEXT(VLOOKUP($A2,'Envio diario'!$B:$J,7,0),"0.000,00"),TEXT(VLOOKUP($A2,'Envio diario'!$B:$J,7,0),"0,00"))), "@realfat", IF(VLOOKUP($A2,'Envio diario'!$B:$J,8,0)>100,TEXT(VLOOKUP($A2,'Envio diario'!$B:$J,8,0),"0.000,00"),TEXT(VLOOKUP($A2,'Envio diario'!$B:$J,8,0),"0,00"))), "@realgar", IF(VLOOKUP($A2,'Envio diario'!$B:$J,9,0)>100,TEXT(VLOOKUP($A2,'Envio diario'!$B:$J,9,0),"0.000,00"),TEXT(VLOOKUP($A2,'Envio diario'!$B:$J,9,0),"0,00"))), "@realobj", IF(VLOOKUP($A2,'Envio diario'!$B:$J,10,0)>100,TEXT(VLOOKUP($A2,'Envio diario'!$B:$J,10,0),"0.000,00"),TEXT(VLOOKUP($A2,'Envio diario'!$B:$J,10,0),"0,00"))), "@perf", TEXT(VLOOKUP($A2,'Envio diario'!$B:$J,11,0),"0,00%") ), "@falta", IF(VLOOKUP($A2,'Envio diario'!$B:$J,12,0)>100,TEXT(VLOOKUP($A2,'Envio diario'!$B:$J,12,0),"0.000,00"),TEXT(VLOOKUP($A2,'Envio diario'!$B:$J,12,0),"0,00"))) -> #REF! | D2: =IF(IFERROR(VLOOKUP(A2,'E-mails'!A:H,8,FALSE),"PROBLEMA!")=0,"",IFERROR(VLOOKUP(A2,'E-mails'!A:H,8,FALSE),"PROBLEMA!")) -> gerencia.psc@mallon.com.br;gerencia.pecas@mallon.com.br;pecas.m3@mallon.com.br;gerencia.psc2@mallon.com.br;coordenadorpsc.rl@mallon.com.br; | E2: =IF(VLOOKUP(A2,'E-mails'!A:G,7,FALSE)=0,"",VLOOKUP(A2,'E-mails'!A:G,7,FALSE)) | F2: =IF(D2<>"","Sim","Não") -> Sim
A3: 40020196 | B3: =CONCATENATE("Faturamento de Peças Vans Agosto 2024 - ",A3," - ",TEXT('Envio diario'!$D$1,"dd/mmm/aaaa")) -> Faturamento de Peças Vans Agosto 2024 - 40020196 - 09/mar/2026 | C3: =SUBSTITUTE(SUBSTITUTE(SUBSTITUTE(SUBSTITUTE(SUBSTITUTE(SUBSTITUTE(SUBSTITUTE(SUBSTITUTE(SUBSTITUTE(SUBSTITUTE(SUBSTITUTE( Corpo!$A$1, "@data", TEXT('Envio diario'!$D$1,"dd/mmm/aaaa") ), "@conta", $A3 ), "@razao", VLOOKUP($A3,'Envio diario'!$B:$J,2,0) ), "@cidade", VLOOKUP($A3,'Envio diario'!$B:$J,3,0) ), "@uf", IF(VLOOKUP($A3,'Envio diario'!$B:$J,4,0)>100,TEXT(VLOOKUP($A3,'Envio diario'!$B:$J,4,0),"0.000,00"),TEXT(VLOOKUP($A3,'Envio diario'!$B:$J,4,0),"0,00"))), "@objetivo", IF(VLOOKUP($A3,'Envio diario'!$B:$J,7,0)>100,TEXT(VLOOKUP($A3,'Envio diario'!$B:$J,7,0),"0.000,00"),TEXT(VLOOKUP($A3,'Envio diario'!$B:$J,7,0),"0,00"))), "@realfat", IF(VLOOKUP($A3,'Envio diario'!$B:$J,8,0)>100,TEXT(VLOOKUP($A3,'Envio diario'!$B:$J,8,0),"0.000,00"),TEXT(VLOOKUP($A3,'Envio diario'!$B:$J,8,0),"0,00"))), "@realgar", IF(VLOOKUP($A3,'Envio diario'!$B:$J,9,0)>100,TEXT(VLOOKUP($A3,'Envio diario'!$B:$J,9,0),"0.000,00"),TEXT(VLOOKUP($A3,'Envio diario'!$B:$J,9,0),"0,00"))), "@realobj", IF(VLOOKUP($A3,'Envio diario'!$B:$J,10,0)>100,TEXT(VLOOKUP($A3,'Envio diario'!$B:$J,10,0),"0.000,00"),TEXT(VLOOKUP($A3,'Envio diario'!$B:$J,10,0),"0,00"))), "@perf", TEXT(VLOOKUP($A3,'Envio diario'!$B:$J,11,0),"0,00%") ), "@falta", IF(VLOOKUP($A3,'Envio diario'!$B:$J,12,0)>100,TEXT(VLOOKUP($A3,'Envio diario'!$B:$J,12,0),"0.000,00"),TEXT(VLOOKUP($A3,'Envio diario'!$B:$J,12,0),"0,00"))) -> #REF! | D3: =IF(IFERROR(VLOOKUP(A3,'E-mails'!A:H,8,FALSE),"PROBLEMA!")=0,"",IFERROR(VLOOKUP(A3,'E-mails'!A:H,8,FALSE),"PROBLEMA!")) -> gerencia.psc@mallon.com.br;gerencia.pecas@mallon.com.br;pecas.m3@mallon.com.br;gerencia.psc2@mallon.com.br;coordenadorpsc.rl@mallon.com.br; | E3: =IF(VLOOKUP(A3,'E-mails'!A:G,7,FALSE)=0,"",VLOOKUP(A3,'E-mails'!A:G,7,FALSE)) | F3: =IF(D3<>"","Sim","Não") -> Sim
A4: 40020197 | B4: =CONCATENATE("Faturamento de Peças Vans Agosto 2024 - ",A4," - ",TEXT('Envio diario'!$D$1,"dd/mmm/aaaa")) -> Faturamento de Peças Vans Agosto 2024 - 40020197 - 09/mar/2026 | C4: =SUBSTITUTE(SUBSTITUTE(SUBSTITUTE(SUBSTITUTE(SUBSTITUTE(SUBSTITUTE(SUBSTITUTE(SUBSTITUTE(SUBSTITUTE(SUBSTITUTE(SUBSTITUTE( Corpo!$A$1, "@data", TEXT('Envio diario'!$D$1,"dd/mmm/aaaa") ), "@conta", $A4 ), "@razao", VLOOKUP($A4,'Envio diario'!$B:$J,2,0) ), "@cidade", VLOOKUP($A4,'Envio diario'!$B:$J,3,0) ), "@uf", IF(VLOOKUP($A4,'Envio diario'!$B:$J,4,0)>100,TEXT(VLOOKUP($A4,'Envio diario'!$B:$J,4,0),"0.000,00"),TEXT(VLOOKUP($A4,'Envio diario'!$B:$J,4,0),"0,00"))), "@objetivo", IF(VLOOKUP($A4,'Envio diario'!$B:$J,7,0)>100,TEXT(VLOOKUP($A4,'Envio diario'!$B:$J,7,0),"0.000,00"),TEXT(VLOOKUP($A4,'Envio diario'!$B:$J,7,0),"0,00"))), "@realfat", IF(VLOOKUP($A4,'Envio diario'!$B:$J,8,0)>100,TEXT(VLOOKUP($A4,'Envio diario'!$B:$J,8,0),"0.000,00"),TEXT(VLOOKUP($A4,'Envio diario'!$B:$J,8,0),"0,00"))), "@realgar", IF(VLOOKUP($A4,'Envio diario'!$B:$J,9,0)>100,TEXT(VLOOKUP($A4,'Envio diario'!$B:$J,9,0),"0.000,00"),TEXT(VLOOKUP($A4,'Envio diario'!$B:$J,9,0),"0,00"))), "@realobj", IF(VLOOKUP($A4,'Envio diario'!$B:$J,10,0)>100,TEXT(VLOOKUP($A4,'Envio diario'!$B:$J,10,0),"0.000,00"),TEXT(VLOOKUP($A4,'Envio diario'!$B:$J,10,0),"0,00"))), "@perf", TEXT(VLOOKUP($A4,'Envio diario'!$B:$J,11,0),"0,00%") ), "@falta", IF(VLOOKUP($A4,'Envio diario'!$B:$J,12,0)>100,TEXT(VLOOKUP($A4,'Envio diario'!$B:$J,12,0),"0.000,00"),TEXT(VLOOKUP($A4,'Envio diario'!$B:$J,12,0),"0,00"))) -> #REF! | D4: =IF(IFERROR(VLOOKUP(A4,'E-mails'!A:H,8,FALSE),"PROBLEMA!")=0,"",IFERROR(VLOOKUP(A4,'E-mails'!A:H,8,FALSE),"PROBLEMA!")) -> gerencia.psc@mallon.com.br;gerencia.pecas@mallon.com.br;pecas.m3@mallon.com.br;gerencia.psc2@mallon.com.br;coordenadorpsc.rl@mallon.com.br; | E4: =IF(VLOOKUP(A4,'E-mails'!A:G,7,FALSE)=0,"",VLOOKUP(A4,'E-mails'!A:G,7,FALSE)) | F4: =IF(D4<>"","Sim","Não") -> Sim
A5: 40544114 | B5: =CONCATENATE("Faturamento de Peças Vans Agosto 2024 - ",A5," - ",TEXT('Envio diario'!$D$1,"dd/mmm/aaaa")) -> Faturamento de Peças Vans Agosto 2024 - 40544114 - 09/mar/2026 | C5: =SUBSTITUTE(SUBSTITUTE(SUBSTITUTE(SUBSTITUTE(SUBSTITUTE(SUBSTITUTE(SUBSTITUTE(SUBSTITUTE(SUBSTITUTE(SUBSTITUTE(SUBSTITUTE( Corpo!$A$1, "@data", TEXT('Envio diario'!$D$1,"dd/mmm/aaaa") ), "@conta", $A5 ), "@razao", VLOOKUP($A5,'Envio diario'!$B:$J,2,0) ), "@cidade", VLOOKUP($A5,'Envio diario'!$B:$J,3,0) ), "@uf", IF(VLOOKUP($A5,'Envio diario'!$B:$J,4,0)>100,TEXT(VLOOKUP($A5,'Envio diario'!$B:$J,4,0),"0.000,00"),TEXT(VLOOKUP($A5,'Envio diario'!$B:$J,4,0),"0,00"))), "@objetivo", IF(VLOOKUP($A5,'Envio diario'!$B:$J,7,0)>100,TEXT(VLOOKUP($A5,'Envio diario'!$B:$J,7,0),"0.000,00"),TEXT(VLOOKUP($A5,'Envio diario'!$B:$J,7,0),"0,00"))), "@realfat", IF(VLOOKUP($A5,'Envio diario'!$B:$J,8,0)>100,TEXT(VLOOKUP($A5,'Envio diario'!$B:$J,8,0),"0.000,00"),TEXT(VLOOKUP($A5,'Envio diario'!$B:$J,8,0),"0,00"))), "@realgar", IF(VLOOKUP($A5,'Envio diario'!$B:$J,9,0)>100,TEXT(VLOOKUP($A5,'Envio diario'!$B:$J,9,0),"0.000,00"),TEXT(VLOOKUP($A5,'Envio diario'!$B:$J,9,0),"0,00"))), "@realobj", IF(VLOOKUP($A5,'Envio diario'!$B:$J,10,0)>100,TEXT(VLOOKUP($A5,'Envio diario'!$B:$J,10,0),"0.000,00"),TEXT(VLOOKUP($A5,'Envio diario'!$B:$J,10,0),"0,00"))), "@perf", TEXT(VLOOKUP($A5,'Envio diario'!$B:$J,11,0),"0,00%") ), "@falta", IF(VLOOKUP($A5,'Envio diario'!$B:$J,12,0)>100,TEXT(VLOOKUP($A5,'Envio diario'!$B:$J,12,0),"0.000,00"),TEXT(VLOOKUP($A5,'Envio diario'!$B:$J,12,0),"0,00"))) -> #REF! | D5: =IF(IFERROR(VLOOKUP(A5,'E-mails'!A:H,8,FALSE),"PROBLEMA!")=0,"",IFERROR(VLOOKUP(A5,'E-mails'!A:H,8,FALSE),"PROBLEMA!")) -> gerencia.psc@mallon.com.br;gerencia.pecas@mallon.com.br;pecas.m3@mallon.com.br;gerencia.psc2@mallon.com.br;coordenadorpsc.rl@mallon.com.br; | E5: =IF(VLOOKUP(A5,'E-mails'!A:G,7,FALSE)=0,"",VLOOKUP(A5,'E-mails'!A:G,7,FALSE)) | F5: =IF(D5<>"","Sim","Não") -> Sim
A6: 40539258 | B6: =CONCATENATE("Faturamento de Peças Vans Agosto 2024 - ",A6," - ",TEXT('Envio diario'!$D$1,"dd/mmm/aaaa")) -> Faturamento de Peças Vans Agosto 2024 - 40539258 - 09/mar/2026 | C6: =SUBSTITUTE(SUBSTITUTE(SUBSTITUTE(SUBSTITUTE(SUBSTITUTE(SUBSTITUTE(SUBSTITUTE(SUBSTITUTE(SUBSTITUTE(SUBSTITUTE(SUBSTITUTE( Corpo!$A$1, "@data", TEXT('Envio diario'!$D$1,"dd/mmm/aaaa") ), "@conta", $A6 ), "@razao", VLOOKUP($A6,'Envio diario'!$B:$J,2,0) ), "@cidade", VLOOKUP($A6,'Envio diario'!$B:$J,3,0) ), "@uf", IF(VLOOKUP($A6,'Envio diario'!$B:$J,4,0)>100,TEXT(VLOOKUP($A6,'Envio diario'!$B:$J,4,0),"0.000,00"),TEXT(VLOOKUP($A6,'Envio diario'!$B:$J,4,0),"0,00"))), "@objetivo", IF(VLOOKUP($A6,'Envio diario'!$B:$J,7,0)>100,TEXT(VLOOKUP($A6,'Envio diario'!$B:$J,7,0),"0.000,00"),TEXT(VLOOKUP($A6,'Envio diario'!$B:$J,7,0),"0,00"))), "@realfat", IF(VLOOKUP($A6,'Envio diario'!$B:$J,8,0)>100,TEXT(VLOOKUP($A6,'Envio diario'!$B:$J,8,0),"0.000,00"),TEXT(VLOOKUP($A6,'Envio diario'!$B:$J,8,0),"0,00"))), "@realgar", IF(VLOOKUP($A6,'Envio diario'!$B:$J,9,0)>100,TEXT(VLOOKUP($A6,'Envio diario'!$B:$J,9,0),"0.000,00"),TEXT(VLOOKUP($A6,'Envio diario'!$B:$J,9,0),"0,00"))), "@realobj", IF(VLOOKUP($A6,'Envio diario'!$B:$J,10,0)>100,TEXT(VLOOKUP($A6,'Envio diario'!$B:$J,10,0),"0.000,00"),TEXT(VLOOKUP($A6,'Envio diario'!$B:$J,10,0),"0,00"))), "@perf", TEXT(VLOOKUP($A6,'Envio diario'!$B:$J,11,0),"0,00%") ), "@falta", IF(VLOOKUP($A6,'Envio diario'!$B:$J,12,0)>100,TEXT(VLOOKUP($A6,'Envio diario'!$B:$J,12,0),"0.000,00"),TEXT(VLOOKUP($A6,'Envio diario'!$B:$J,12,0),"0,00"))) -> #REF! | D6: =IF(IFERROR(VLOOKUP(A6,'E-mails'!A:H,8,FALSE),"PROBLEMA!")=0,"",IFERROR(VLOOKUP(A6,'E-mails'!A:H,8,FALSE),"PROBLEMA!")) -> compras@unidasmercedesbenz.com.br; | E6: =IF(VLOOKUP(A6,'E-mails'!A:G,7,FALSE)=0,"",VLOOKUP(A6,'E-mails'!A:G,7,FALSE)) | F6: =IF(D6<>"","Sim","Não") -> Sim
A7: 40503343 | B7: =CONCATENATE("Faturamento de Peças Vans Agosto 2024 - ",A7," - ",TEXT('Envio diario'!$D$1,"dd/mmm/aaaa")) -> Faturamento de Peças Vans Agosto 2024 - 40503343 - 09/mar/2026 | C7: =SUBSTITUTE(SUBSTITUTE(SUBSTITUTE(SUBSTITUTE(SUBSTITUTE(SUBSTITUTE(SUBSTITUTE(SUBSTITUTE(SUBSTITUTE(SUBSTITUTE(SUBSTITUTE( Corpo!$A$1, "@data", TEXT('Envio diario'!$D$1,"dd/mmm/aaaa") ), "@conta", $A7 ), "@razao", VLOOKUP($A7,'Envio diario'!$B:$J,2,0) ), "@cidade", VLOOKUP($A7,'Envio diario'!$B:$J,3,0) ), "@uf", IF(VLOOKUP($A7,'Envio diario'!$B:$J,4,0)>100,TEXT(VLOOKUP($A7,'Envio diario'!$B:$J,4,0),"0.000,00"),TEXT(VLOOKUP($A7,'Envio diario'!$B:$J,4,0),"0,00"))), "@objetivo", IF(VLOOKUP($A7,'Envio diario'!$B:$J,7,0)>100,TEXT(VLOOKUP($A7,'Envio diario'!$B:$J,7,0),"0.000,00"),TEXT(VLOOKUP($A7,'Envio diario'!$B:$J,7,0),"0,00"))), "@realfat", IF(VLOOKUP($A7,'Envio diario'!$B:$J,8,0)>100,TEXT(VLOOKUP($A7,'Envio diario'!$B:$J,8,0),"0.000,00"),TEXT(VLOOKUP($A7,'Envio diario'!$B:$J,8,0),"0,00"))), "@realgar", IF(VLOOKUP($A7,'Envio diario'!$B:$J,9,0)>100,TEXT(VLOOKUP($A7,'Envio diario'!$B:$J,9,0),"0.000,00"),TEXT(VLOOKUP($A7,'Envio diario'!$B:$J,9,0),"0,00"))), "@realobj", IF(VLOOKUP($A7,'Envio diario'!$B:$J,10,0)>100,TEXT(VLOOKUP($A7,'Envio diario'!$B:$J,10,0),"0.000,00"),TEXT(VLOOKUP($A7,'Envio diario'!$B:$J,10,0),"0,00"))), "@perf", TEXT(VLOOKUP($A7,'Envio diario'!$B:$J,11,0),"0,00%") ), "@falta", IF(VLOOKUP($A7,'Envio diario'!$B:$J,12,0)>100,TEXT(VLOOKUP($A7,'Envio diario'!$B:$J,12,0),"0.000,00"),TEXT(VLOOKUP($A7,'Envio diario'!$B:$J,12,0),"0,00"))) -> #REF! | D7: =IF(IFERROR(VLOOKUP(A7,'E-mails'!A:H,8,FALSE),"PROBLEMA!")=0,"",IFERROR(VLOOKUP(A7,'E-mails'!A:H,8,FALSE),"PROBLEMA!")) -> leyliane.lopes@stacaminhoes.com.br;diego.angelo@stacaminhoes.com.br;compras@stacaminhoes.com.br;caio@stacaminhoes.com.br;jose.luiz@stacaminhoes.com.br; | E7: =IF(VLOOKUP(A7,'E-mails'!A:G,7,FALSE)=0,"",VLOOKUP(A7,'E-mails'!A:G,7,FALSE)) | F7: =IF(D7<>"","Sim","Não") -> Sim
A8: 40018371 | B8: =CONCATENATE("Faturamento de Peças Vans Agosto 2024 - ",A8," - ",TEXT('Envio diario'!$D$1,"dd/mmm/aaaa")) -> Faturamento de Peças Vans Agosto 2024 - 40018371 - 09/mar/2026 | C8: =SUBSTITUTE(SUBSTITUTE(SUBSTITUTE(SUBSTITUTE(SUBSTITUTE(SUBSTITUTE(SUBSTITUTE(SUBSTITUTE(SUBSTITUTE(SUBSTITUTE(SUBSTITUTE( Corpo!$A$1, "@data", TEXT('Envio diario'!$D$1,"dd/mmm/aaaa") ), "@conta", $A8 ), "@razao", VLOOKUP($A8,'Envio diario'!$B:$J,2,0) ), "@cidade", VLOOKUP($A8,'Envio diario'!$B:$J,3,0) ), "@uf", IF(VLOOKUP($A8,'Envio diario'!$B:$J,4,0)>100,TEXT(VLOOKUP($A8,'Envio diario'!$B:$J,4,0),"0.000,00"),TEXT(VLOOKUP($A8,'Envio diario'!$B:$J,4,0),"0,00"))), "@objetivo", IF(VLOOKUP($A8,'Envio diario'!$B:$J,7,0)>100,TEXT(VLOOKUP($A8,'Envio diario'!$B:$J,7,0),"0.000,00"),TEXT(VLOOKUP($A8,'Envio diario'!$B:$J,7,0),"0,00"))), "@realfat", IF(VLOOKUP($A8,'Envio diario'!$B:$J,8,0)>100,TEXT(VLOOKUP($A8,'Envio diario'!$B:$J,8,0),"0.000,00"),TEXT(VLOOKUP($A8,'Envio diario'!$B:$J,8,0),"0,00"))), "@realgar", IF(VLOOKUP($A8,'Envio diario'!$B:$J,9,0)>100,TEXT(VLOOKUP($A8,'Envio diario'!$B:$J,9,0),"0.000,00"),TEXT(VLOOKUP($A8,'Envio diario'!$B:$J,9,0),"0,00"))), "@realobj", IF(VLOOKUP($A8,'Envio diario'!$B:$J,10,0)>100,TEXT(VLOOKUP($A8,'Envio diario'!$B:$J,10,0),"0.000,00"),TEXT(VLOOKUP($A8,'Envio diario'!$B:$J,10,0),"0,00"))), "@perf", TEXT(VLOOKUP($A8,'Envio diario'!$B:$J,11,0),"0,00%") ), "@falta", IF(VLOOKUP($A8,'Envio diario'!$B:$J,12,0)>100,TEXT(VLOOKUP($A8,'Envio diario'!$B:$J,12,0),"0.000,00"),TEXT(VLOOKUP($A8,'Envio diario'!$B:$J,12,0),"0,00"))) -> #REF! | D8: =IF(IFERROR(VLOOKUP(A8,'E-mails'!A:H,8,FALSE),"PROBLEMA!")=0,"",IFERROR(VLOOKUP(A8,'E-mails'!A:H,8,FALSE),"PROBLEMA!")) -> compras@stacaminhoes.com.br;caio@stacaminhoes.com.br;jose.luiz@stacaminhoes.com.br; | E8: =IF(VLOOKUP(A8,'E-mails'!A:G,7,FALSE)=0,"",VLOOKUP(A8,'E-mails'!A:G,7,FALSE)) | F8: =IF(D8<>"","Sim","Não") -> Sim
A9: 40026401 | B9: =CONCATENATE("Faturamento de Peças Vans Agosto 2024 - ",A9," - ",TEXT('Envio diario'!$D$1,"dd/mmm/aaaa")) -> Faturamento de Peças Vans Agosto 2024 - 40026401 - 09/mar/2026 | C9: =SUBSTITUTE(SUBSTITUTE(SUBSTITUTE(SUBSTITUTE(SUBSTITUTE(SUBSTITUTE(SUBSTITUTE(SUBSTITUTE(SUBSTITUTE(SUBSTITUTE(SUBSTITUTE( Corpo!$A$1, "@data", TEXT('Envio diario'!$D$1,"dd/mmm/aaaa") ), "@conta", $A9 ), "@razao", VLOOKUP($A9,'Envio diario'!$B:$J,2,0) ), "@cidade", VLOOKUP($A9,'Envio diario'!$B:$J,3,0) ), "@uf", IF(VLOOKUP($A9,'Envio diario'!$B:$J,4,0)>100,TEXT(VLOOKUP($A9,'Envio diario'!$B:$J,4,0),"0.000,00"),TEXT(VLOOKUP($A9,'Envio diario'!$B:$J,4,0),"0,00"))), "@objetivo", IF(VLOOKUP($A9,'Envio diario'!$B:$J,7,0)>100,TEXT(VLOOKUP($A9,'Envio diario'!$B:$J,7,0),"0.000,00"),TEXT(VLOOKUP($A9,'Envio diario'!$B:$J,7,0),"0,00"))), "@realfat", IF(VLOOKUP($A9,'Envio diario'!$B:$J,8,0)>100,TEXT(VLOOKUP($A9,'Envio diario'!$B:$J,8,0),"0.000,00"),TEXT(VLOOKUP($A9,'Envio diario'!$B:$J,8,0),"0,00"))), "@realgar", IF(VLOOKUP($A9,'Envio diario'!$B:$J,9,0)>100,TEXT(VLOOKUP($A9,'Envio diario'!$B:$J,9,0),"0.000,00"),TEXT(VLOOKUP($A9,'Envio diario'!$B:$J,9,0),"0,00"))), "@realobj", IF(VLOOKUP($A9,'Envio diario'!$B:$J,10,0)>100,TEXT(VLOOKUP($A9,'Envio diario'!$B:$J,10,0),"0.000,00"),TEXT(VLOOKUP($A9,'Envio diario'!$B:$J,10,0),"0,00"))), "@perf", TEXT(VLOOKUP($A9,'Envio diario'!$B:$J,11,0),"0,00%") ), "@falta", IF(VLOOKUP($A9,'Envio diario'!$B:$J,12,0)>100,TEXT(VLOOKUP($A9,'Envio diario'!$B:$J,12,0),"0.000,00"),TEXT(VLOOKUP($A9,'Envio diario'!$B:$J,12,0),"0,00"))) -> #REF! | D9: =IF(IFERROR(VLOOKUP(A9,'E-mails'!A:H,8,FALSE),"PROBLEMA!")=0,"",IFERROR(VLOOKUP(A9,'E-mails'!A:H,8,FALSE),"PROBLEMA!")) -> leyliane.lopes@unidasmercedesbenz.com.br;diego.angelo@unidasmercedesbenz.com.br;compras@unidasmercedesbenz.com.br; | E9: =IF(VLOOKUP(A9,'E-mails'!A:G,7,FALSE)=0,"",VLOOKUP(A9,'E-mails'!A:G,7,FALSE)) | F9: =IF(D9<>"","Sim","Não") -> Sim
A10: 40018338 | B10: =CONCATENATE("Faturamento de Peças Vans Agosto 2024 - ",A10," - ",TEXT('Envio diario'!$D$1,"dd/mmm/aaaa")) -> Faturamento de Peças Vans Agosto 2024 - 40018338 - 09/mar/2026 | C10: =SUBSTITUTE(SUBSTITUTE(SUBSTITUTE(SUBSTITUTE(SUBSTITUTE(SUBSTITUTE(SUBSTITUTE(SUBSTITUTE(SUBSTITUTE(SUBSTITUTE(SUBSTITUTE( Corpo!$A$1, "@data", TEXT('Envio diario'!$D$1,"dd/mmm/aaaa") ), "@conta", $A10 ), "@razao", VLOOKUP($A10,'Envio diario'!$B:$J,2,0) ), "@cidade", VLOOKUP($A10,'Envio diario'!$B:$J,3,0) ), "@uf", IF(VLOOKUP($A10,'Envio diario'!$B:$J,4,0)>100,TEXT(VLOOKUP($A10,'Envio diario'!$B:$J,4,0),"0.000,00"),TEXT(VLOOKUP($A10,'Envio diario'!$B:$J,4,0),"0,00"))), "@objetivo", IF(VLOOKUP($A10,'Envio diario'!$B:$J,7,0)>100,TEXT(VLOOKUP($A10,'Envio diario'!$B:$J,7,0),"0.000,00"),TEXT(VLOOKUP($A10,'Envio diario'!$B:$J,7,0),"0,00"))), "@realfat", IF(VLOOKUP($A10,'Envio diario'!$B:$J,8,0)>100,TEXT(VLOOKUP($A10,'Envio diario'!$B:$J,8,0),"0.000,00"),TEXT(VLOOKUP($A10,'Envio diario'!$B:$J,8,0),"0,00"))), "@realgar", IF(VLOOKUP($A10,'Envio diario'!$B:$J,9,0)>100,TEXT(VLOOKUP($A10,'Envio diario'!$B:$J,9,0),"0.000,00"),TEXT(VLOOKUP($A10,'Envio diario'!$B:$J,9,0),"0,00"))), "@realobj", IF(VLOOKUP($A10,'Envio diario'!$B:$J,10,0)>100,TEXT(VLOOKUP($A10,'Envio diario'!$B:$J,10,0),"0.000,00"),TEXT(VLOOKUP($A10,'Envio diario'!$B:$J,10,0),"0,00"))), "@perf", TEXT(VLOOKUP($A10,'Envio diario'!$B:$J,11,0),"0,00%") ), "@falta", IF(VLOOKUP($A10,'Envio diario'!$B:$J,12,0)>100,TEXT(VLOOKUP($A10,'Envio diario'!$B:$J,12,0),"0.000,00"),TEXT(VLOOKUP($A10,'Envio diario'!$B:$J,12,0),"0,00"))) -> #REF! | D10: =IF(IFERROR(VLOOKUP(A10,'E-mails'!A:H,8,FALSE),"PROBLEMA!")=0,"",IFERROR(VLOOKUP(A10,'E-mails'!A:H,8,FALSE),"PROBLEMA!")) -> diego.angelo@stacaminhoes.com.br;compras@stacaminhoes.com.br;leyliane.lopes@stacaminhoes.com.br;caio@stacaminhoes.com.br;jose.luiz@stacaminhoes.com.br; | E10: =IF(VLOOKUP(A10,'E-mails'!A:G,7,FALSE)=0,"",VLOOKUP(A10,'E-mails'!A:G,7,FALSE)) | F10: =IF(D10<>"","Sim","Não") -> Sim
A11: 40527450 | B11: =CONCATENATE("Faturamento de Peças Vans Agosto 2024 - ",A11," - ",TEXT('Envio diario'!$D$1,"dd/mmm/aaaa")) -> Faturamento de Peças Vans Agosto 2024 - 40527450 - 09/mar/2026 | C11: =SUBSTITUTE(SUBSTITUTE(SUBSTITUTE(SUBSTITUTE(SUBSTITUTE(SUBSTITUTE(SUBSTITUTE(SUBSTITUTE(SUBSTITUTE(SUBSTITUTE(SUBSTITUTE( Corpo!$A$1, "@data", TEXT('Envio diario'!$D$1,"dd/mmm/aaaa") ), "@conta", $A11 ), "@razao", VLOOKUP($A11,'Envio diario'!$B:$J,2,0) ), "@cidade", VLOOKUP($A11,'Envio diario'!$B:$J,3,0) ), "@uf", IF(VLOOKUP($A11,'Envio diario'!$B:$J,4,0)>100,TEXT(VLOOKUP($A11,'Envio diario'!$B:$J,4,0),"0.000,00"),TEXT(VLOOKUP($A11,'Envio diario'!$B:$J,4,0),"0,00"))), "@objetivo", IF(VLOOKUP($A11,'Envio diario'!$B:$J,7,0)>100,TEXT(VLOOKUP($A11,'Envio diario'!$B:$J,7,0),"0.000,00"),TEXT(VLOOKUP($A11,'Envio diario'!$B:$J,7,0),"0,00"))), "@realfat", IF(VLOOKUP($A11,'Envio diario'!$B:$J,8,0)>100,TEXT(VLOOKUP($A11,'Envio diario'!$B:$J,8,0),"0.000,00"),TEXT(VLOOKUP($A11,'Envio diario'!$B:$J,8,0),"0,00"))), "@realgar", IF(VLOOKUP($A11,'Envio diario'!$B:$J,9,0)>100,TEXT(VLOOKUP($A11,'Envio diario'!$B:$J,9,0),"0.000,00"),TEXT(VLOOKUP($A11,'Envio diario'!$B:$J,9,0),"0,00"))), "@realobj", IF(VLOOKUP($A11,'Envio diario'!$B:$J,10,0)>100,TEXT(VLOOKUP($A11,'Envio diario'!$B:$J,10,0),"0.000,00"),TEXT(VLOOKUP($A11,'Envio diario'!$B:$J,10,0),"0,00"))), "@perf", TEXT(VLOOKUP($A11,'Envio diario'!$B:$J,11,0),"0,00%") ), "@falta", IF(VLOOKUP($A11,'Envio diario'!$B:$J,12,0)>100,TEXT(VLOOKUP($A11,'Envio diario'!$B:$J,12,0),"0.000,00"),TEXT(VLOOKUP($A11,'Envio diario'!$B:$J,12,0),"0,00"))) -> #REF! | D11: =IF(IFERROR(VLOOKUP(A11,'E-mails'!A:H,8,FALSE),"PROBLEMA!")=0,"",IFERROR(VLOOKUP(A11,'E-mails'!A:H,8,FALSE),"PROBLEMA!")) -> compras@vitoriadiesel.com.br; DouglasRamos@aguiabranca.com.br; ; FilipeMastela@vitoriadiesel.com.br;RafaelL@aguiabranca.com.br; | E11: =IF(VLOOKUP(A11,'E-mails'!A:G,7,FALSE)=0,"",VLOOKUP(A11,'E-mails'!A:G,7,FALSE)) | F11: =IF(D11<>"","Sim","Não") -> Sim
A12: 40527486 | B12: =CONCATENATE("Faturamento de Peças Vans Agosto 2024 - ",A12," - ",TEXT('Envio diario'!$D$1,"dd/mmm/aaaa")) -> Faturamento de Peças Vans Agosto 2024 - 40527486 - 09/mar/2026 | C12: =SUBSTITUTE(SUBSTITUTE(SUBSTITUTE(SUBSTITUTE(SUBSTITUTE(SUBSTITUTE(SUBSTITUTE(SUBSTITUTE(SUBSTITUTE(SUBSTITUTE(SUBSTITUTE( Corpo!$A$1, "@data", TEXT('Envio diario'!$D$1,"dd/mmm/aaaa") ), "@conta", $A12 ), "@razao", VLOOKUP($A12,'Envio diario'!$B:$J,2,0) ), "@cidade", VLOOKUP($A12,'Envio diario'!$B:$J,3,0) ), "@uf", IF(VLOOKUP($A12,'Envio diario'!$B:$J,4,0)>100,TEXT(VLOOKUP($A12,'Envio diario'!$B:$J,4,0),"0.000,00"),TEXT(VLOOKUP($A12,'Envio diario'!$B:$J,4,0),"0,00"))), "@objetivo", IF(VLOOKUP($A12,'Envio diario'!$B:$J,7,0)>100,TEXT(VLOOKUP($A12,'Envio diario'!$B:$J,7,0),"0.000,00"),TEXT(VLOOKUP($A12,'Envio diario'!$B:$J,7,0),"0,00"))), "@realfat", IF(VLOOKUP($A12,'Envio diario'!$B:$J,8,0)>100,TEXT(VLOOKUP($A12,'Envio diario'!$B:$J,8,0),"0.000,00"),TEXT(VLOOKUP($A12,'Envio diario'!$B:$J,8,0),"0,00"))), "@realgar", IF(VLOOKUP($A12,'Envio diario'!$B:$J,9,0)>100,TEXT(VLOOKUP($A12,'Envio diario'!$B:$J,9,0),"0.000,00"),TEXT(VLOOKUP($A12,'Envio diario'!$B:$J,9,0),"0,00"))), "@realobj", IF(VLOOKUP($A12,'Envio diario'!$B:$J,10,0)>100,TEXT(VLOOKUP($A12,'Envio diario'!$B:$J,10,0),"0.000,00"),TEXT(VLOOKUP($A12,'Envio diario'!$B:$J,10,0),"0,00"))), "@perf", TEXT(VLOOKUP($A12,'Envio diario'!$B:$J,11,0),"0,00%") ), "@falta", IF(VLOOKUP($A12,'Envio diario'!$B:$J,12,0)>100,TEXT(VLOOKUP($A12,'Envio diario'!$B:$J,12,0),"0.000,00"),TEXT(VLOOKUP($A12,'Envio diario'!$B:$J,12,0),"0,00"))) -> #REF! | D12: =IF(IFERROR(VLOOKUP(A12,'E-mails'!A:H,8,FALSE),"PROBLEMA!")=0,"",IFERROR(VLOOKUP(A12,'E-mails'!A:H,8,FALSE),"PROBLEMA!")) -> compras@vitoriadiesel.com.br;DouglasRamos@aguiabranca.com.br;;ValdecirB@savana.com.br;edsong@savana.com.br;RafaelL@aguiabranca.com.br; | E12: =IF(VLOOKUP(A12,'E-mails'!A:G,7,FALSE)=0,"",VLOOKUP(A12,'E-mails'!A:G,7,FALSE)) | F12: =IF(D12<>"","Sim","Não") -> Sim
A13: 40535094 | B13: =CONCATENATE("Faturamento de Peças Vans Agosto 2024 - ",A13," - ",TEXT('Envio diario'!$D$1,"dd/mmm/aaaa")) -> Faturamento de Peças Vans Agosto 2024 - 40535094 - 09/mar/2026 | C13: =SUBSTITUTE(SUBSTITUTE(SUBSTITUTE(SUBSTITUTE(SUBSTITUTE(SUBSTITUTE(SUBSTITUTE(SUBSTITUTE(SUBSTITUTE(SUBSTITUTE(SUBSTITUTE( Corpo!$A$1, "@data", TEXT('Envio diario'!$D$1,"dd/mmm/aaaa") ), "@conta", $A13 ), "@razao", VLOOKUP($A13,'Envio diario'!$B:$J,2,0) ), "@cidade", VLOOKUP($A13,'Envio diario'!$B:$J,3,0) ), "@uf", IF(VLOOKUP($A13,'Envio diario'!$B:$J,4,0)>100,TEXT(VLOOKUP($A13,'Envio diario'!$B:$J,4,0),"0.000,00"),TEXT(VLOOKUP($A13,'Envio diario'!$B:$J,4,0),"0,00"))), "@objetivo", IF(VLOOKUP($A13,'Envio diario'!$B:$J,7,0)>100,TEXT(VLOOKUP($A13,'Envio diario'!$B:$J,7,0),"0.000,00"),TEXT(VLOOKUP($A13,'Envio diario'!$B:$J,7,0),"0,00"))), "@realfat", IF(VLOOKUP($A13,'Envio diario'!$B:$J,8,0)>100,TEXT(VLOOKUP($A13,'Envio diario'!$B:$J,8,0),"0.000,00"),TEXT(VLOOKUP($A13,'Envio diario'!$B:$J,8,0),"0,00"))), "@realgar", IF(VLOOKUP($A13,'Envio diario'!$B:$J,9,0)>100,TEXT(VLOOKUP($A13,'Envio diario'!$B:$J,9,0),"0.000,00"),TEXT(VLOOKUP($A13,'Envio diario'!$B:$J,9,0),"0,00"))), "@realobj", IF(VLOOKUP($A13,'Envio diario'!$B:$J,10,0)>100,TEXT(VLOOKUP($A13,'Envio diario'!$B:$J,10,0),"0.000,00"),TEXT(VLOOKUP($A13,'Envio diario'!$B:$J,10,0),"0,00"))), "@perf", TEXT(VLOOKUP($A13,'Envio diario'!$B:$J,11,0),"0,00%") ), "@falta", IF(VLOOKUP($A13,'Envio diario'!$B:$J,12,0)>100,TEXT(VLOOKUP($A13,'Envio diario'!$B:$J,12,0),"0.000,00"),TEXT(VLOOKUP($A13,'Envio diario'!$B:$J,12,0),"0,00"))) -> #REF! | D13: =IF(IFERROR(VLOOKUP(A13,'E-mails'!A:H,8,FALSE),"PROBLEMA!")=0,"",IFERROR(VLOOKUP(A13,'E-mails'!A:H,8,FALSE),"PROBLEMA!")) -> compras@vitoriadiesel.com.br;DouglasRamos@aguiabranca.com.br;;FilipeMastela@vitoriadiesel.com.br;FranciscoAssis@vitoriadiesel.com.br;RafaelL@aguiabranca.com.br; | E13: =IF(VLOOKUP(A13,'E-mails'!A:G,7,FALSE)=0,"",VLOOKUP(A13,'E-mails'!A:G,7,FALSE)) | F13: =IF(D13<>"","Sim","Não") -> Sim
... A181: 40023907 | B181: =CONCATENATE("Faturamento de Peças Vans Agosto 2024 - ",A181," - ",TEXT('Envio diario'!$D$1,"dd/mmm/aaaa")) -> Faturamento de Peças Vans Agosto 2024 - 40023907 - 09/mar/2026 | C181: =SUBSTITUTE(SUBSTITUTE(SUBSTITUTE(SUBSTITUTE(SUBSTITUTE(SUBSTITUTE(SUBSTITUTE(SUBSTITUTE(SUBSTITUTE(SUBSTITUTE(SUBSTITUTE( Corpo!$A$1, "@data", TEXT('Envio diario'!$D$1,"dd/mmm/aaaa") ), "@conta", $A181 ), "@razao", VLOOKUP($A181,'Envio diario'!$B:$J,2,0) ), "@cidade", VLOOKUP($A181,'Envio diario'!$B:$J,3,0) ), "@uf", IF(VLOOKUP($A181,'Envio diario'!$B:$J,4,0)>100,TEXT(VLOOKUP($A181,'Envio diario'!$B:$J,4,0),"0.000,00"),TEXT(VLOOKUP($A181,'Envio diario'!$B:$J,4,0),"0,00"))), "@objetivo", IF(VLOOKUP($A181,'Envio diario'!$B:$J,7,0)>100,TEXT(VLOOKUP($A181,'Envio diario'!$B:$J,7,0),"0.000,00"),TEXT(VLOOKUP($A181,'Envio diario'!$B:$J,7,0),"0,00"))), "@realfat", IF(VLOOKUP($A181,'Envio diario'!$B:$J,8,0)>100,TEXT(VLOOKUP($A181,'Envio diario'!$B:$J,8,0),"0.000,00"),TEXT(VLOOKUP($A181,'Envio diario'!$B:$J,8,0),"0,00"))), "@realgar", IF(VLOOKUP($A181,'Envio diario'!$B:$J,9,0)>100,TEXT(VLOOKUP($A181,'Envio diario'!$B:$J,9,0),"0.000,00"),TEXT(VLOOKUP($A181,'Envio diario'!$B:$J,9,0),"0,00"))), "@realobj", IF(VLOOKUP($A181,'Envio diario'!$B:$J,10,0)>100,TEXT(VLOOKUP($A181,'Envio diario'!$B:$J,10,0),"0.000,00"),TEXT(VLOOKUP($A181,'Envio diario'!$B:$J,10,0),"0,00"))), "@perf", TEXT(VLOOKUP($A181,'Envio diario'!$B:$J,11,0),"0,00%") ), "@falta", IF(VLOOKUP($A181,'Envio diario'!$B:$J,12,0)>100,TEXT(VLOOKUP($A181,'Envio diario'!$B:$J,12,0),"0.000,00"),TEXT(VLOOKUP($A181,'Envio diario'!$B:$J,12,0),"0,00"))) -> #N/A | D181: =IF(IFERROR(VLOOKUP(A181,'E-mails'!A:H,8,FALSE),"PROBLEMA!")=0,"",IFERROR(VLOOKUP(A181,'E-mails'!A:H,8,FALSE),"PROBLEMA!")) -> centraldecomprasholding@grupovdl.com.br; herlon.costa@grupovdl.com.br; carlos.oliveira@grupovdl.com.br; jefferson.duarte@grupovdl.com.br; | E181: =IF(VLOOKUP(A181,'E-mails'!A:G,7,FALSE)=0,"",VLOOKUP(A181,'E-mails'!A:G,7,FALSE)) | F181: =IF(D181<>"","Sim","Não") -> Sim

Sheet E-mails
A1: Conta | B1: Consultor | C1: Razão Social | D1: Município | E1: UF | F1: Grupo | G1: E-mail Consultor | H1: E-mails
A2: 40532251 | B2: Camilo | C2: MALLON CONCESSIONÁRIA DE VEÍCULOS COMERCIAIS LTDA. | D2: Lages | E2: SC | F2: A Mallon | H2: gerencia.psc@mallon.com.br;gerencia.pecas@mallon.com.br;pecas.m3@mallon.com.br;gerencia.psc2@mallon.com.br;coordenadorpsc.rl@mallon.com.br;
A3: 40020196 | B3: Camilo | C3: VEÍCULOS MALLON LTDA. | D3: União Da Vitória | E3: PR | F3: A Mallon | H3: gerencia.psc@mallon.com.br;gerencia.pecas@mallon.com.br;pecas.m3@mallon.com.br;gerencia.psc2@mallon.com.br;coordenadorpsc.rl@mallon.com.br;
A4: 40020197 | B4: Camilo | C4: VEÍCULOS MALLON LTDA. | D4: Mafra | E4: SC | F4: A Mallon | H4: gerencia.psc@mallon.com.br;gerencia.pecas@mallon.com.br;pecas.m3@mallon.com.br;gerencia.psc2@mallon.com.br;coordenadorpsc.rl@mallon.com.br;
A5: 40544114 | B5: Camilo | C5: MALLON CONCESSIONÁRIA DE VEÍCULOS COMERCIAIS LTDA. | D5: Rio Do Sul | E5: SC | F5: A Mallon | H5: gerencia.psc@mallon.com.br;gerencia.pecas@mallon.com.br;pecas.m3@mallon.com.br;gerencia.psc2@mallon.com.br;coordenadorpsc.rl@mallon.com.br;
A6: 40026401 | B6: Marcelo | C6: UNIDAS VEÍCULOS E SERVIÇOS LTDA. | D6: Campina Grande | E6: PB | F6: A. Cândido | H6: leyliane.lopes@unidasmercedesbenz.com.br;diego.angelo@unidasmercedesbenz.com.br;compras@unidasmercedesbenz.com.br;
A7: 40503343 | B7: Marcelo | C7: STA CAMINHOES RN VEICULOS E SERVICOS LTDA | D7: Mossoró | E7: RN | F7: A. Cândido | H7: leyliane.lopes@stacaminhoes.com.br;diego.angelo@stacaminhoes.com.br;compras@stacaminhoes.com.br;caio@stacaminhoes.com.br;jose.luiz@stacaminhoes.com.br;
A8: 40018338 | B8: Marcelo | C8: STA CAMINHOES RN VEICULOS E SERVICOS LTDA | D8: Natal | E8: RN | F8: A. Cândido | H8: diego.angelo@stacaminhoes.com.br;compras@stacaminhoes.com.br;leyliane.lopes@stacaminhoes.com.br;caio@stacaminhoes.com.br;jose.luiz@stacaminhoes.com.br;
A9: 40539258 | B9: Marcelo | C9: UNIDAS VEÍCULOS E SERVIÇOS LTDA. | D9: Patos | E9: PB | F9: A. Cândido | H9: compras@unidasmercedesbenz.com.br;
A10: 40018371 | B10: Marcelo | C10: STA CAMINHOES VEICULOS E SERVICOS L | D10: João Pessoa | E10: PB | F10: A. Cândido | H10: compras@stacaminhoes.com.br;caio@stacaminhoes.com.br;jose.luiz@stacaminhoes.com.br;
A11: 40520260 | B11: Odilon | C11: SAVANA COMÉRCIO DE VEÍCULOS LTDA. | D11: Curitiba | E11: PR | F11: Águia Branca | H11: compras@vitoriadiesel.com.br;DouglasRamos@aguiabranca.com.br;;ValdecirB@savana.com.br;Anderson@savana.com.br;RafaelL@aguiabranca.com.br;
A12: 40519448 | B12: Odilon | C12: SAVANA COMÉRCIO DE VEÍCULOS LTDA. | D12: São José dos Pinhais | E12: PR | F12: Águia Branca | H12: compras@vitoriadiesel.com.br;DouglasRamos@aguiabranca.com.br;;ValdecirB@savana.com.br;Anderson@savana.com.br;RafaelL@aguiabranca.com.br;
A13: 40018620 | B13: Leonardo | C13: VD COMÉRCIO DE VEÍCULOS LTDA. | D13: Cariacica | E13: ES | F13: Águia Branca | H13: compras@vitoriadiesel.com.br;DouglasRamos@aguiabranca.com.br;;FilipeMastela@vitoriadiesel.com.br;Max@vitoriadiesel.com.br;RafaelL@aguiabranca.com.br;
... A51: 40022459 | B51: Alexandre | C51: DE NIGRIS DISTRIBUIDORA DE VEÍCULOS LTDA. | D51: Itu | E51: SP | F51: De Nigris | H51: lucas.almeida@denigris.com.br;arlei.bethiol@denigris.com.br;ailton.barboza@denigris.com.br;rodrigo.pugas@denigris.com.br;
A52: 40529553 | B52: Alexandre | C52: COMERCIAL DE VEÍCULOS DE NIGRIS LTDA | D52: São Bernardo Do Campo | E52: SP | F52: De Nigris | H52: #N/A
A53: 40017542 | B53: Alexandre | C53: COMERCIAL DE VEÍCULOS DE NIGRIS LTDA | D53: São Bernado Do Campo | E53: SP | F53: De Nigris | H53: alexandre.acedo@denigris.com.br; caique.pereira@denigris.com.br;
A54: 40016660 | B54: Odilon | C54: DE NIGRIS DISTRIBUIDORA DE VEÍCULOS LTDA. | D54: São Paulo | E54: SP | F54: De Nigris | H54: sidnei.almeida@denigris.com.br;compras.pecas@denigris.com.br; jbertoco@denigris.com.br ;marcos.luiz@denigris.com.br;
A55: 40020194 | B55: Odilon | C55: DE NIGRIS DISTRIBUIDORA DE VEÍCULOS LTDA. | D55: Guarulhos | E55: SP | F55: De Nigris | H55: sidnei.almeida@denigris.com.br; compras.pecas@denigris.com.br; jbertoco@denigris.com.br ;marcos.luiz@denigris.com.br;
A56: 40022487 | B56: Odilon | C56: DE NIGRIS DISTRIBUIDORA DE VEÍCULOS LTDA. | D56: São Paulo | E56: SP | F56: De Nigris | H56: sidnei.almeida@denigris.com.br;compras.pecas@denigris.com.br; jbertoco@denigris.com.br ;marcos.luiz@denigris.com.br;
A57: 40017178 | B57: Martinez | C57: DIVENA COMERCIAL LTDA | D57: Barueri | E57: SP | F57: Divena | H57: mariluce.vilarim@divena.com.br; mauricio.moraes@divena.com.br; jenniffer.patricia@divena.com.br; altair.moreira@divena.com.br;luiz.oliveira@divena.com.br; jose.rocha@divena.com.br;
A58: 40516443 | B58: Martinez | C58: DIVENA COMERCIAL LTDA | D58: Diadema | E58: SP | F58: Divena | H58: mariluce.vilarim@divena.com.br; mauricio.moraes@divena.com.br; jenniffer.patricia@divena.com.br; altair.moreira@divena.com.br;luiz.oliveira@divena.com.br; jose.rocha@divena.com.br;compras.comercial@divena.com.br;
A59: 40024018 | B59: Martinez | C59: DIVENA LITORAL VEÍCULOS LTDA. | D59: Santos | E59: SP | F59: Divena | H59: mariluce.vilarim@divena.com.br; mauricio.moraes@divena.com.br; jenniffer.patricia@divena.com.br; altair.moreira@divena.com.br;luiz.oliveira@divena.com.br; jose.rocha@divena.com.br;compras.comercial@divena.com.br;
A60: 40551984 | B60: Leonardo | C60: GUANABARA DIESEL S.A. COMÉRCIO E REPRESENTAÇÕES | D60: Barra Mansa | E60: RJ | F60: Jacob Barata | H60: marcio.moraes@gbdiesel.com.br; Sidney.cardoso@gbdiesel.com.br; alexandre.silva@gbdiesel.com.br;
A61: 40543682 | B61: Marcelo | C61: IDISA VEÍCULOS LTDA. | D61: Medianeira | E61: PR | F61: Idisa | H61: elton@idisa.com.br;
A62: 40543694 | B62: Marcelo | C62: IDISA VEÍCULOS LTDA. | D62: Marechal Candido Rondon | E62: PR | F62: Idisa | H62: elton@idisa.com.br;
A63: 40022479 | B63: Marcelo | C63: IDISA VEÍCULOS LTDA. | D63: Foz Do Iguaçu | E63: PR | F63: Idisa | H63: elton@idisa.com.br;
A64: 40002980 | B64: Martinez | C64: BLU STAR COMÉRCIO DE VEÍCULOS LTDA. | D64: Indaial | E64: SC | F64: Independente | H64: tiago@blustar.com.br;
A65: 40018503 | B65: Camilo | C65: PARANÁ DIESEL VEÍCULOS LTDA. | D65: Campo Mourão | E65: PR | F65: Independente | H65: fabio.stormoski@sperandiodiesel.com.br; leandro@paranadiesel.com.br; pecas@paranadiesel.com.br;pecas4@paranadiesel.com.br;
A66: 40001181 | B66: Martinez | C66: PAULISTA AUTO DIESEL LTDA. | D66: Lucélia | E66: SP | F66: Independente
A67: 40017533 | B67: Alexandre | C67: COSMAR VEÍCULOS E MÁQUINAS LTDA. | D67: Jundiaí | E67: SP | F67: Independente | H67: juliano@cosmar.com.br; weverton@cosmar.com.br;
A68: 40023803 | B68: Marcelo | C68: JAGUARDIESEL - JAGUARIBE DIESEL LTDA. | D68: Jaguaribe | E68: CE | F68: Independente | H68: abnerdiogenes@jaguardiesel.com.br; jeiverpinheiro@jaguardiesel.com.br; antoniaemilia@jaguardiesel.com.br;
A69: 40017152 | B69: Odilon | C69: ACREDIESEL COMERCIAL DE VEÍCULOS LTDA. | D69: Rio Branco | E69: AC | F69: Independente | H69: elson.passos@acrediesel.com.br; paulo.provenza@acrediesel.com.br;
A70: 40553712 | B70: Leonardo | C70: MINASMÁQUINAS S.A. | D70: Ubá | E70: MG | F70: Minasmáquinas | H70: willerwm@minasmaquinas.com.br; enilson@minasmaquinas.com.br; adriano.magalhaes@minasmaquinas.com.br; wesley.rodrigues@minasmaquinas.com.br; aiana.santos@minasmaquinas.com.br; thalles.vilela@minasmaquinas.com.br; daiana.santos@minasmaquinas.com.br;
A71: 40020190 | B71: Camilo | C71: ENZO CAMINHÕES LTDA. | D71: Dourados | E71: MS | F71: Independente | H71: roberto.pereira@enzocaminhoes.com.br; alexandro.zuconelli@grupoenzo.com.br; walcy.silva@grupoenzo.com.br;mauro.rios@enzocaminhoes.com.br;
A72: 40006162 | B72: Leonardo | C72: RIO DIESEL VEÍCULOS E PEÇAS S.A. | D72: Nova Iguaçú | E72: RJ | F72: Independente | H72: vladimir.miolaro@riodiesel.com.br; anderson.castilho@riodiesel.com.br; conrado.nascimento@riodiesel.com.br; felipe.xavier@riodiesel.com.br;
A73: 40007564 | B73: Leonardo | C73: MIRIAM MINAS RIO, AUTOMÓVEIS E MÁQUINAS S.A. | D73: Rio De Janeiro | E73: RJ | F73: Independente | H73: francisco@miriam.com.br; posvenda@miriam.com.br; gabriela@miriam.com.br; jrv@miriam.com.br;milton@miriam.com.br;
A74: 40011003 | B74: Marcelo | C74: AGRICOL DIESEL LTDA. | D74: São Paulo | E74: SP | F74: Independente | H74: rafael@agricol.com.br; claudiosilva@agricol.com.br;
A75: 40017284 | B75: Leonardo | C75: WERNER & CIA. LTDA. | D75: Manhuaçú | E75: MG | F75: Independente
A76: 40025031 | B76: Martinez | C76: VEGRANDE VEÍCULOS CASAGRANDE S.A. | D76: Guarapuava | E76: PR | F76: Ingá | H76: marciano.galvao@ingaveiculos.com.br;paulo.clausen@ingaveiculos.com.br;
A77: 40022457 | B77: Martinez | C77: INGÁ VEÍCULOS LTDA. | D77: Itajaí | E77: SC | F77: Ingá | H77: david.borges@ingaveiculos.com.br;paulo.clausen@ingaveiculos.com.br;
...

Sheet Envio diario
C1: sim | D1: 46090 | E1: Relatório de Vendas de Peças – VANS MB (Gross) – Março/2026 | N1: 0.25 | O1: 0.5 | P1: 0.75 | Q1: 1
C2: Não | E2: =SUBTOTAL(9,E4:E169) -> 23742173 | F2: =SUBTOTAL(9,F4:F169) -> 8699314 | G2: =SUBTOTAL(9,G4:G169) -> 1008186.6 | H2: =SUBTOTAL(9,H4:H169) -> 7691127.4 | I2: =IFERROR(H2/E2,0) -> 0.32394371 | J2: =SUBTOTAL(9,J4:J169) -> -16051045 | K2: =SUBTOTAL(9,K4:K169) -> 1194710.1 | N2: 46087 | O2: 46094 | P2: 46104 | Q2: 46112
A3: Consultor | B3: Conta | C3: Razão Social | D3: Cidade/UF | E3: Objetivo | F3: Gross | G3: R20 | H3: Realizado | I3: Performance | J3: Falta 100% | K3: Pipeline | L3: Grupo | M3: DMS | N3: Reg. 1ºSem | O3: Reg. 2ºSem | P3: Reg. 3ºSem | Q3: Reg. 4º Sem
A4: Camilo | B4: 40532251 | C4: MALLON CONCESSIONÁRIA DE VEÍCULOS COMERCIAIS LTDA. | D4: Lages-SC | E4: 64891.69 | F4: 43200.01 | G4: 0 | H4: =F4-G4 -> 43200.01 | I4: =IFERROR(H4/E4,0) -> 0.66572484 | J4: =H4-E4 -> -21691.68 | K4: 3448.93 | L4: A Mallon | M4: MICROWORK | N4: =IF(I4>$N$1,$C$1,$C$2) -> sim | O4: =IF(I4>$O$1,$C$1,$C$2) -> sim | P4: =IF(I4>$P$1,$C$1,$C$2) -> Não | Q4: =IF(I4>$Q$1,$C$1,$C$2) -> Não
A5: Camilo | B5: 40020197 | C5: VEÍCULOS MALLON LTDA. | D5: Mafra-SC | E5: 64927.29 | F5: 23970.15 | G5: 889.75 | H5: =F5-G5 -> 23080.4 | I5: =IFERROR(H5/E5,0) -> 0.35548072 | J5: =H5-E5 -> -41846.89 | K5: 1166.27 | L5: A Mallon | M5: MICROWORK | N5: =IF(I5>$N$1,$C$1,$C$2) -> sim | O5: =IF(I5>$O$1,$C$1,$C$2) -> Não | P5: =IF(I5>$P$1,$C$1,$C$2) -> Não | Q5: =IF(I5>$Q$1,$C$1,$C$2) -> Não
A6: Camilo | B6: 40544114 | C6: MALLON CONCESSIONÁRIA DE VEÍCULOS COMERCIAIS LTDA. | D6: Rio Do Sul-SC | E6: 161878.72 | F6: 34957.97 | G6: 391.34 | H6: =F6-G6 -> 34566.63 | I6: =IFERROR(H6/E6,0) -> 0.21353412 | J6: =H6-E6 -> -127312.09 | K6: 36957.64 | L6: A Mallon | M6: MICROWORK | N6: =IF(I6>$N$1,$C$1,$C$2) -> Não | O6: =IF(I6>$O$1,$C$1,$C$2) -> Não | P6: =IF(I6>$P$1,$C$1,$C$2) -> Não | Q6: =IF(I6>$Q$1,$C$1,$C$2) -> Não
A7: Camilo | B7: 40020196 | C7: VEÍCULOS MALLON LTDA. | D7: União Da Vitória-PR | E7: 28319.46 | F7: 2517.98 | G7: 0 | H7: =F7-G7 -> 2517.98 | I7: =IFERROR(H7/E7,0) -> 0.088913419 | J7: =H7-E7 -> -25801.48 | K7: 1021.8 | L7: A Mallon | M7: MICROWORK | N7: =IF(I7>$N$1,$C$1,$C$2) -> Não | O7: =IF(I7>$O$1,$C$1,$C$2) -> Não | P7: =IF(I7>$P$1,$C$1,$C$2) -> Não | Q7: =IF(I7>$Q$1,$C$1,$C$2) -> Não
A8: Marcelo | B8: 40026401 | C8: UNIDAS VEÍCULOS E SERVIÇOS LTDA. | D8: Campina Grande-PB | E8: 64401.279 | F8: 46025.38 | G8: 0 | H8: =F8-G8 -> 46025.38 | I8: =IFERROR(H8/E8,0) -> 0.71466562 | J8: =H8-E8 -> -18375.899 | K8: 2091.94 | L8: A. Cândido | M8: MICROWORK | N8: =IF(I8>$N$1,$C$1,$C$2) -> sim | O8: =IF(I8>$O$1,$C$1,$C$2) -> sim | P8: =IF(I8>$P$1,$C$1,$C$2) -> Não | Q8: =IF(I8>$Q$1,$C$1,$C$2) -> Não
A9: Marcelo | B9: 40018371 | C9: STA CAMINHOES VEICULOS E SERVICOS L | D9: João Pessoa-PB | E9: 136989.86 | F9: 56545.58 | G9: 0 | H9: =F9-G9 -> 56545.58 | I9: =IFERROR(H9/E9,0) -> 0.41277202 | J9: =H9-E9 -> -80444.278 | K9: 5368.38 | L9: A. Cândido | M9: MICROWORK | N9: =IF(I9>$N$1,$C$1,$C$2) -> sim | O9: =IF(I9>$O$1,$C$1,$C$2) -> Não | P9: =IF(I9>$P$1,$C$1,$C$2) -> Não | Q9: =IF(I9>$Q$1,$C$1,$C$2) -> Não
A10: Marcelo | B10: 40503343 | C10: STA CAMINHOES RN VEICULOS E SERVICOS LTDA | D10: Mossoró-RN | E10: 33710.607 | F10: 16292.29 | G10: 0 | H10: =F10-G10 -> 16292.29 | I10: =IFERROR(H10/E10,0) -> 0.48329862 | J10: =H10-E10 -> -17418.318 | K10: 1750.54 | L10: A. Cândido | M10: MICROWORK | N10: =IF(I10>$N$1,$C$1,$C$2) -> sim | O10: =IF(I10>$O$1,$C$1,$C$2) -> Não | P10: =IF(I10>$P$1,$C$1,$C$2) -> Não | Q10: =IF(I10>$Q$1,$C$1,$C$2) -> Não
A11: Marcelo | B11: 40018338 | C11: STA CAMINHOES RN VEICULOS E SERVICOS LTDA | D11: Natal-RN | E11: 151507.4 | F11: 103459.53 | G11: 0 | H11: =F11-G11 -> 103459.53 | I11: =IFERROR(H11/E11,0) -> 0.68286783 | J11: =H11-E11 -> -48047.87 | K11: 358.71 | L11: A. Cândido | M11: MICROWORK | N11: =IF(I11>$N$1,$C$1,$C$2) -> sim | O11: =IF(I11>$O$1,$C$1,$C$2) -> sim | P11: =IF(I11>$P$1,$C$1,$C$2) -> Não | Q11: =IF(I11>$Q$1,$C$1,$C$2) -> Não
A12: Marcelo | B12: 40539258 | C12: UNIDAS VEÍCULOS E SERVIÇOS LTDA. | D12: Patos-PB | E12: 51049.039 | F12: 21088.69 | G12: 0 | H12: =F12-G12 -> 21088.69 | I12: =IFERROR(H12/E12,0) -> 0.41310651 | J12: =H12-E12 -> -29960.349 | K12: 0 | L12: A. Cândido | M12: MICROWORK | N12: =IF(I12>$N$1,$C$1,$C$2) -> sim | O12: =IF(I12>$O$1,$C$1,$C$2) -> Não | P12: =IF(I12>$P$1,$C$1,$C$2) -> Não | Q12: =IF(I12>$Q$1,$C$1,$C$2) -> Não
A13: Leonardo | B13: 40500897 | C13: VD COMÉRCIO DE VEÍCULOS LTDA. | D13: Cachoeiro De Itapemirim-ES | E13: 95000 | F13: 2090.25 | G13: 0 | H13: =F13-G13 -> 2090.25 | I13: =IFERROR(H13/E13,0) -> 0.022002632 | J13: =H13-E13 -> -92909.75 | K13: 1123.82 | L13: Águia Branca | M13: NBS | N13: =IF(I13>$N$1,$C$1,$C$2) -> Não | O13: =IF(I13>$O$1,$C$1,$C$2) -> Não | P13: =IF(I13>$P$1,$C$1,$C$2) -> Não | Q13: =IF(I13>$Q$1,$C$1,$C$2) -> Não
A14: Leonardo | B14: 40018620 | C14: VD COMÉRCIO DE VEÍCULOS LTDA. | D14: Cariacica-ES | E14: 693500 | F14: 119578.11 | G14: 10419.82 | H14: =F14-G14 -> 109158.29 | I14: =IFERROR(H14/E14,0) -> 0.157402 | J14: =H14-E14 -> -584341.71 | K14: 195874.61 | L14: Águia Branca | M14: NBS | N14: =IF(I14>$N$1,$C$1,$C$2) -> Não | O14: =IF(I14>$O$1,$C$1,$C$2) -> Não | P14: =IF(I14>$P$1,$C$1,$C$2) -> Não | Q14: =IF(I14>$Q$1,$C$1,$C$2) -> Não
A15: Leonardo | B15: 40535094 | C15: VD COMÉRCIO DE VEÍCULOS LTDA. | D15: Colatina-ES | E15: 125000 | F15: 22122.91 | G15: 2698.02 | H15: =F15-G15 -> 19424.89 | I15: =IFERROR(H15/E15,0) -> 0.15539912 | J15: =H15-E15 -> -105575.11 | K15: 6617.77 | L15: Águia Branca | M15: NBS | N15: =IF(I15>$N$1,$C$1,$C$2) -> Não | O15: =IF(I15>$O$1,$C$1,$C$2) -> Não | P15: =IF(I15>$P$1,$C$1,$C$2) -> Não | Q15: =IF(I15>$Q$1,$C$1,$C$2) -> Não
... A169: Alexandre | B169: 40555746 | C169: IRMÃOS DAVOLI S.A. IMPORTAÇÃO E COMÉRCIO | D169: Amparo - SP | E169: 42343.054 | F169: 5389.11 | G169: 64.37 | H169: =F169-G169 -> 5324.74 | I169: =IFERROR(H169/E169,0) -> 0.12575239 | J169: =H169-E169 -> -37018.314 | K169: 655.8 | L169: Irmãos Davoli | M169: MICROWORK | N169: =IF(I169>$N$1,$C$1,$C$2) -> Não | O169: =IF(I169>$O$1,$C$1,$C$2) -> Não | P169: =IF(I169>$P$1,$C$1,$C$2) -> Não | Q169: =IF(I169>$Q$1,$C$1,$C$2) -> Não

Sheet NRCP
A1: Vans | B1: Valores | F1: =IF(A1>$N$1,$C$1,$C$2) -> 0
A2: 46082 | B2: Rede | I2: 45231 | J2: 400000 | K2: -157453.87 | L2: =K2/B$15 -> -0.011246705
A3: Objetivo Rede | B3: ='Envio diario'!E2 -> 23742173 | D3: =B15 -> 14000000 | I3: 45233 | J3: 400000 | K3: 2000000 | L3: =K3/B$15 -> 0.14285714
A4: Falta Objetivo | B4: =B11-B3 -> -16051045 | I4: 45236 | J4: 400000 | L4: =K4/B$15 -> 0
A5: Performance | B5: =B11/B3 -> 0.32394371 | D5: =D11/D3 -> 0.33223894 | I5: 45237 | J5: 400000 | L5: =K5/B$15 -> 0
I6: 45238 | J6: 400000 | L6: =K6/B$15 -> 0
A7: Realizado Geral | B7: ='Envio diario'!F2 -> 8699314 | C7: 0.6888 | D7: =B7*C7 -> 5992087.5 | E7: Logistica | I7: 45239 | J7: 400000 | L7: =K7/B$15 -> 0
A8: Realizado (CL 5562-02201) | B8: 7742275.4 | C8: 0.6888 | D8: =B8*C8 -> 5332879.3 | I8: 45240 | J8: 400000 | L8: =K8/B$15 -> 0
A9: Garantia R20 Gross | B9: ='Envio diario'!G2 -> 1008186.6 | C9: 0.676 | D9: =B9*C9 -> 681534.13
A10: Devoluções | B10: 0
A11: Realizado c/descontos | B11: ='Envio diario'!H2 -> 7691127.4 | D11: =D8-D9 -> 4651345.2
A13: Vans | B13: Valores
A14: 46082 | B14: em NRCP
A15: Objetivo | B15: 14000000
A16: Falta Objetivo | B16: =B22-B15 -> -9366544.4
A17: Performance | B17: =B22/B15 -> 0.33096111
A18: Realizado | B18: 5314989.7 | C18: Net
A19: Garantia Aqua | B19: =D19*C19 -> 0 | C19: 0.676
A20: Garantia R20 | B20: =D20*C20 -> 681534.13 | C20: 0.676 | D20: =B9 -> 1008186.6
A21: Devoluções
A22: Realizado c/descontos | B22: =B18-B19-B20 -> 4633455.6

Sheet NRCP Diário
A1: Data | B1: Milhão
A2: 46083 | B2: 1554.583
A3: 46084 | B3: 964.80705
A4: 46085 | B4: 912.99017
A5: 46086 | B5: 579.15245
A6: 46087 | B6: 621.924
A26: Total | B26: =SUM(B2:B25) -> 4633.4567
